2024-11-16 15:04:02 __main__     ERROR    Configuration file config.ini not found!
2024-11-16 15:04:02 __main__     ERROR    An error occurred while sending the email:
Traceback (most recent call last):
  File "E:\RSSB\DCC\LPR\Codes\2024\emailSender\main.py", line 114, in <module>
    config = read_config()
  File "E:\RSSB\DCC\LPR\Codes\2024\emailSender\main.py", line 36, in read_config
    raise FileNotFoundError(f"Configuration file {config_path} not found!")
FileNotFoundError: Configuration file config.ini not found!
2024-11-16 15:04:16 __main__     INFO     Preparing to send email...
2024-11-16 15:04:16 __main__     INFO     Sender: "systemalert@mail.dccmail.in"
2024-11-16 15:04:16 __main__     INFO     To: ["user.harpreetsingh@gmail.com"]
2024-11-16 15:04:16 __main__     INFO     Cc: []
2024-11-16 15:04:16 __main__     INFO     Subject: "LPR Email"
2024-11-16 15:04:16 __main__     INFO     Attachment: email_sender.log
2024-11-16 15:04:16 __main__     DEBUG    Email body attached
2024-11-16 15:04:16 __main__     DEBUG    File email_sender.log read successfully
2024-11-16 15:04:16 __main__     DEBUG    File encoded successfully
2024-11-16 15:04:16 __main__     DEBUG    Attachment added to message
2024-11-16 15:04:17 __main__     ERROR    An error occurred while sending the email:
Traceback (most recent call last):
  File "E:\RSSB\DCC\LPR\Codes\2024\emailSender\main.py", line 115, in <module>
    send_email_with_attachment(config)
  File "E:\RSSB\DCC\LPR\Codes\2024\emailSender\main.py", line 96, in send_email_with_attachment
    with smtplib.SMTP(smtp_server, smtp_port) as server:
  File "C:\Users\userh\AppData\Local\Programs\Python\Python39\lib\smtplib.py", line 255, in __init__
    (code, msg) = self.connect(host, port)
  File "C:\Users\userh\AppData\Local\Programs\Python\Python39\lib\smtplib.py", line 341, in connect
    self.sock = self._get_socket(host, port, self.timeout)
  File "C:\Users\userh\AppData\Local\Programs\Python\Python39\lib\smtplib.py", line 312, in _get_socket
    return socket.create_connection((host, port), timeout,
  File "C:\Users\userh\AppData\Local\Programs\Python\Python39\lib\socket.py", line 823, in create_connection
    for res in getaddrinfo(host, port, 0, SOCK_STREAM):
  File "C:\Users\userh\AppData\Local\Programs\Python\Python39\lib\socket.py", line 954, in getaddrinfo
    for res in _socket.getaddrinfo(host, port, family, type, proto, flags):
socket.gaierror: [Errno 11001] getaddrinfo failed
2024-11-16 15:04:40 __main__     INFO     Preparing to send email...
2024-11-16 15:04:40 __main__     INFO     Sender: "systemalert@mail.dccmail.in"
2024-11-16 15:04:40 __main__     INFO     To: ["user.harpreetsingh@gmail.com"]
2024-11-16 15:04:40 __main__     INFO     Cc: []
2024-11-16 15:04:40 __main__     INFO     Subject: "LPR Email"
2024-11-16 15:04:40 __main__     INFO     Attachment: email_sender.log
2024-11-16 15:04:40 __main__     DEBUG    Email body attached
2024-11-16 15:04:40 __main__     DEBUG    File email_sender.log read successfully
2024-11-16 15:04:40 __main__     DEBUG    File encoded successfully
2024-11-16 15:04:40 __main__     DEBUG    Attachment added to message
2024-11-16 15:04:40 __main__     ERROR    An error occurred while sending the email:
Traceback (most recent call last):
  File "E:\RSSB\DCC\LPR\Codes\2024\emailSender\main.py", line 115, in <module>
    send_email_with_attachment(config)
  File "E:\RSSB\DCC\LPR\Codes\2024\emailSender\main.py", line 96, in send_email_with_attachment
    with smtplib.SMTP(smtp_server, smtp_port) as server:
  File "C:\Users\userh\AppData\Local\Programs\Python\Python39\lib\smtplib.py", line 255, in __init__
    (code, msg) = self.connect(host, port)
  File "C:\Users\userh\AppData\Local\Programs\Python\Python39\lib\smtplib.py", line 341, in connect
    self.sock = self._get_socket(host, port, self.timeout)
  File "C:\Users\userh\AppData\Local\Programs\Python\Python39\lib\smtplib.py", line 312, in _get_socket
    return socket.create_connection((host, port), timeout,
  File "C:\Users\userh\AppData\Local\Programs\Python\Python39\lib\socket.py", line 823, in create_connection
    for res in getaddrinfo(host, port, 0, SOCK_STREAM):
  File "C:\Users\userh\AppData\Local\Programs\Python\Python39\lib\socket.py", line 954, in getaddrinfo
    for res in _socket.getaddrinfo(host, port, family, type, proto, flags):
socket.gaierror: [Errno 11001] getaddrinfo failed
2024-11-16 15:05:23 __main__     INFO     Preparing to send email...
2024-11-16 15:05:23 __main__     INFO     Sender: "systemalert@mail.dccmail.in"
2024-11-16 15:05:23 __main__     INFO     To: ["user.harpreetsingh@gmail.com"]
2024-11-16 15:05:23 __main__     INFO     Cc: []
2024-11-16 15:05:23 __main__     INFO     Subject: "LPR Email"
2024-11-16 15:05:23 __main__     INFO     Attachment: email_sender.log
2024-11-16 15:05:23 __main__     DEBUG    Email body attached
2024-11-16 15:05:23 __main__     DEBUG    File email_sender.log read successfully
2024-11-16 15:05:23 __main__     DEBUG    File encoded successfully
2024-11-16 15:05:23 __main__     DEBUG    Attachment added to message
2024-11-16 15:05:23 __main__     ERROR    An error occurred while sending the email:
Traceback (most recent call last):
  File "E:\RSSB\DCC\LPR\Codes\2024\emailSender\main.py", line 115, in <module>
    send_email_with_attachment(config)
  File "E:\RSSB\DCC\LPR\Codes\2024\emailSender\main.py", line 96, in send_email_with_attachment
    with smtplib.SMTP(smtp_server, smtp_port) as server:
  File "C:\Users\userh\AppData\Local\Programs\Python\Python39\lib\smtplib.py", line 255, in __init__
    (code, msg) = self.connect(host, port)
  File "C:\Users\userh\AppData\Local\Programs\Python\Python39\lib\smtplib.py", line 341, in connect
    self.sock = self._get_socket(host, port, self.timeout)
  File "C:\Users\userh\AppData\Local\Programs\Python\Python39\lib\smtplib.py", line 312, in _get_socket
    return socket.create_connection((host, port), timeout,
  File "C:\Users\userh\AppData\Local\Programs\Python\Python39\lib\socket.py", line 823, in create_connection
    for res in getaddrinfo(host, port, 0, SOCK_STREAM):
  File "C:\Users\userh\AppData\Local\Programs\Python\Python39\lib\socket.py", line 954, in getaddrinfo
    for res in _socket.getaddrinfo(host, port, family, type, proto, flags):
socket.gaierror: [Errno 11001] getaddrinfo failed
2024-11-16 15:08:09 __main__     INFO     Preparing to send email...
2024-11-16 15:08:09 __main__     INFO     Sender: "systemalert@mail.dccmail.in"
2024-11-16 15:08:09 __main__     INFO     To: ["user.harpreetsingh@gmail.com"]
2024-11-16 15:08:09 __main__     INFO     Cc: []
2024-11-16 15:08:09 __main__     INFO     Subject: "LPR Email"
2024-11-16 15:08:09 __main__     INFO     Attachment: email_sender.log
2024-11-16 15:08:09 __main__     DEBUG    Email body attached
2024-11-16 15:08:09 __main__     DEBUG    File email_sender.log read successfully
2024-11-16 15:08:09 __main__     DEBUG    File encoded successfully
2024-11-16 15:08:09 __main__     DEBUG    Attachment added to message
2024-11-16 15:08:09 __main__     ERROR    An error occurred while sending the email:
Traceback (most recent call last):
  File "E:\RSSB\DCC\LPR\Codes\2024\emailSender\main.py", line 113, in <module>
    send_email_with_attachment(config)
  File "E:\RSSB\DCC\LPR\Codes\2024\emailSender\main.py", line 96, in send_email_with_attachment
    with smtplib.SMTP_SSL(smtp_server, smtp_port) as server:
  File "C:\Users\userh\AppData\Local\Programs\Python\Python39\lib\smtplib.py", line 1050, in __init__
    SMTP.__init__(self, host, port, local_hostname, timeout,
  File "C:\Users\userh\AppData\Local\Programs\Python\Python39\lib\smtplib.py", line 255, in __init__
    (code, msg) = self.connect(host, port)
  File "C:\Users\userh\AppData\Local\Programs\Python\Python39\lib\smtplib.py", line 341, in connect
    self.sock = self._get_socket(host, port, self.timeout)
  File "C:\Users\userh\AppData\Local\Programs\Python\Python39\lib\smtplib.py", line 1056, in _get_socket
    new_socket = super()._get_socket(host, port, timeout)
  File "C:\Users\userh\AppData\Local\Programs\Python\Python39\lib\smtplib.py", line 312, in _get_socket
    return socket.create_connection((host, port), timeout,
  File "C:\Users\userh\AppData\Local\Programs\Python\Python39\lib\socket.py", line 823, in create_connection
    for res in getaddrinfo(host, port, 0, SOCK_STREAM):
  File "C:\Users\userh\AppData\Local\Programs\Python\Python39\lib\socket.py", line 954, in getaddrinfo
    for res in _socket.getaddrinfo(host, port, family, type, proto, flags):
socket.gaierror: [Errno 11001] getaddrinfo failed
2024-11-16 15:08:39 __main__     INFO     Preparing to send email...
2024-11-16 15:08:39 __main__     INFO     Sender: "systemalert@mail.dccmail.in"
2024-11-16 15:08:39 __main__     INFO     To: ["user.harpreetsingh@gmail.com"]
2024-11-16 15:08:39 __main__     INFO     Cc: []
2024-11-16 15:08:39 __main__     INFO     Subject: "LPR Email"
2024-11-16 15:08:39 __main__     INFO     Attachment: email_sender.log
2024-11-16 15:08:39 __main__     DEBUG    Email body attached
2024-11-16 15:08:39 __main__     DEBUG    File email_sender.log read successfully
2024-11-16 15:08:39 __main__     DEBUG    File encoded successfully
2024-11-16 15:08:39 __main__     DEBUG    Attachment added to message
2024-11-16 15:08:39 __main__     ERROR    An error occurred while sending the email:
Traceback (most recent call last):
  File "E:\RSSB\DCC\LPR\Codes\2024\emailSender\main.py", line 115, in <module>
    send_email_with_attachment(config)
  File "E:\RSSB\DCC\LPR\Codes\2024\emailSender\main.py", line 94, in send_email_with_attachment
    with smtplib.SMTP(smtp_server, smtp_port) as server:
  File "C:\Users\userh\AppData\Local\Programs\Python\Python39\lib\smtplib.py", line 255, in __init__
    (code, msg) = self.connect(host, port)
  File "C:\Users\userh\AppData\Local\Programs\Python\Python39\lib\smtplib.py", line 341, in connect
    self.sock = self._get_socket(host, port, self.timeout)
  File "C:\Users\userh\AppData\Local\Programs\Python\Python39\lib\smtplib.py", line 312, in _get_socket
    return socket.create_connection((host, port), timeout,
  File "C:\Users\userh\AppData\Local\Programs\Python\Python39\lib\socket.py", line 823, in create_connection
    for res in getaddrinfo(host, port, 0, SOCK_STREAM):
  File "C:\Users\userh\AppData\Local\Programs\Python\Python39\lib\socket.py", line 954, in getaddrinfo
    for res in _socket.getaddrinfo(host, port, family, type, proto, flags):
socket.gaierror: [Errno 11001] getaddrinfo failed
2024-11-16 15:15:36 __main__     INFO     Preparing to send email...
2024-11-16 15:15:36 __main__     INFO     Sender: "systemalert@mail.dccmail.in"
2024-11-16 15:15:36 __main__     INFO     To: ["user.harpreetsingh@gmail.com"]
2024-11-16 15:15:36 __main__     INFO     Cc: []
2024-11-16 15:15:36 __main__     INFO     Subject: "LPR Email"
2024-11-16 15:15:36 __main__     INFO     Attachment: email_sender.log
2024-11-16 15:15:36 __main__     DEBUG    Email body attached
2024-11-16 15:15:36 __main__     DEBUG    File email_sender.log read successfully
2024-11-16 15:15:36 __main__     DEBUG    File encoded successfully
2024-11-16 15:15:36 __main__     DEBUG    Attachment added to message
2024-11-16 15:15:36 __main__     ERROR    An error occurred while sending the email:
Traceback (most recent call last):
  File "E:\RSSB\DCC\LPR\Codes\2024\emailSender\main.py", line 114, in <module>
    send_email_with_attachment(config)
  File "E:\RSSB\DCC\LPR\Codes\2024\emailSender\main.py", line 95, in send_email_with_attachment
    with smtplib.SMTP(smtp_server, smtp_port) as server:
  File "C:\Users\userh\AppData\Local\Programs\Python\Python39\lib\smtplib.py", line 255, in __init__
    (code, msg) = self.connect(host, port)
  File "C:\Users\userh\AppData\Local\Programs\Python\Python39\lib\smtplib.py", line 341, in connect
    self.sock = self._get_socket(host, port, self.timeout)
  File "C:\Users\userh\AppData\Local\Programs\Python\Python39\lib\smtplib.py", line 312, in _get_socket
    return socket.create_connection((host, port), timeout,
  File "C:\Users\userh\AppData\Local\Programs\Python\Python39\lib\socket.py", line 823, in create_connection
    for res in getaddrinfo(host, port, 0, SOCK_STREAM):
  File "C:\Users\userh\AppData\Local\Programs\Python\Python39\lib\socket.py", line 954, in getaddrinfo
    for res in _socket.getaddrinfo(host, port, family, type, proto, flags):
socket.gaierror: [Errno 11001] getaddrinfo failed
2024-11-16 15:16:18 __main__     INFO     Preparing to send email...
2024-11-16 15:16:18 __main__     INFO     Sender: "systemalert@mail.dccmail.in"
2024-11-16 15:16:18 __main__     INFO     To: ["user.harpreetsingh@gmail.com"]
2024-11-16 15:16:18 __main__     INFO     Cc: []
2024-11-16 15:16:18 __main__     INFO     Subject: "LPR Email"
2024-11-16 15:16:18 __main__     INFO     Attachment: email_sender.log
2024-11-16 15:16:18 __main__     DEBUG    Email body attached
2024-11-16 15:16:18 __main__     DEBUG    File email_sender.log read successfully
2024-11-16 15:16:18 __main__     DEBUG    File encoded successfully
2024-11-16 15:16:18 __main__     DEBUG    Attachment added to message
2024-11-16 15:16:18 __main__     INFO     Attempting to connect to SMTP server: "mail.dccmail.in"
2024-11-16 15:16:18 __main__     ERROR    Failed to resolve server: [Errno 11001] getaddrinfo failed
2024-11-16 15:16:18 __main__     ERROR    An error occurred while sending the email: [Errno 11001] getaddrinfo failed
2024-11-16 15:16:18 __main__     ERROR    An error occurred while sending the email:
Traceback (most recent call last):
  File "E:\RSSB\DCC\LPR\Codes\2024\emailSender\main.py", line 122, in <module>
    send_email_with_attachment(config)
  File "E:\RSSB\DCC\LPR\Codes\2024\emailSender\main.py", line 97, in send_email_with_attachment
    server_ip = socket.gethostbyname(smtp_server)
socket.gaierror: [Errno 11001] getaddrinfo failed
2024-11-16 15:17:01 __main__     INFO     Preparing to send email...
2024-11-16 15:17:01 __main__     INFO     Sender: "systemalert@mail.dccmail.in"
2024-11-16 15:17:01 __main__     INFO     To: ["user.harpreetsingh@gmail.com"]
2024-11-16 15:17:01 __main__     INFO     Cc: []
2024-11-16 15:17:01 __main__     INFO     Subject: "LPR Email"
2024-11-16 15:17:01 __main__     INFO     Attachment: email_sender.log
2024-11-16 15:17:01 __main__     DEBUG    Email body attached
2024-11-16 15:17:01 __main__     DEBUG    File email_sender.log read successfully
2024-11-16 15:17:01 __main__     DEBUG    File encoded successfully
2024-11-16 15:17:01 __main__     DEBUG    Attachment added to message
2024-11-16 15:17:01 __main__     INFO     Attempting to connect to SMTP server: "mail.dccmail.in"
2024-11-16 15:17:01 __main__     INFO     Successfully resolved server to 122.184.75.61
2024-11-16 15:17:01 __main__     ERROR    An error occurred while sending the email: [Errno 11001] getaddrinfo failed
2024-11-16 15:17:01 __main__     ERROR    An error occurred while sending the email:
Traceback (most recent call last):
  File "E:\RSSB\DCC\LPR\Codes\2024\emailSender\main.py", line 122, in <module>
    send_email_with_attachment(config)
  File "E:\RSSB\DCC\LPR\Codes\2024\emailSender\main.py", line 103, in send_email_with_attachment
    with smtplib.SMTP(smtp_server, smtp_port) as server:
  File "C:\Users\userh\AppData\Local\Programs\Python\Python39\lib\smtplib.py", line 255, in __init__
    (code, msg) = self.connect(host, port)
  File "C:\Users\userh\AppData\Local\Programs\Python\Python39\lib\smtplib.py", line 341, in connect
    self.sock = self._get_socket(host, port, self.timeout)
  File "C:\Users\userh\AppData\Local\Programs\Python\Python39\lib\smtplib.py", line 312, in _get_socket
    return socket.create_connection((host, port), timeout,
  File "C:\Users\userh\AppData\Local\Programs\Python\Python39\lib\socket.py", line 823, in create_connection
    for res in getaddrinfo(host, port, 0, SOCK_STREAM):
  File "C:\Users\userh\AppData\Local\Programs\Python\Python39\lib\socket.py", line 954, in getaddrinfo
    for res in _socket.getaddrinfo(host, port, family, type, proto, flags):
socket.gaierror: [Errno 11001] getaddrinfo failed
2024-11-16 15:17:38 __main__     INFO     Preparing to send email...
2024-11-16 15:17:38 __main__     INFO     Sender: "systemalert@mail.dccmail.in"
2024-11-16 15:17:38 __main__     INFO     To: ["user.harpreetsingh@gmail.com"]
2024-11-16 15:17:38 __main__     INFO     Cc: []
2024-11-16 15:17:38 __main__     INFO     Subject: "LPR Email"
2024-11-16 15:17:38 __main__     INFO     Attachment: email_sender.log
2024-11-16 15:17:38 __main__     DEBUG    Email body attached
2024-11-16 15:17:38 __main__     DEBUG    File email_sender.log read successfully
2024-11-16 15:17:38 __main__     DEBUG    File encoded successfully
2024-11-16 15:17:38 __main__     DEBUG    Attachment added to message
2024-11-16 15:17:38 __main__     INFO     Attempting to connect to SMTP server: "mail.dccmail.in"
2024-11-16 15:17:38 __main__     INFO     Successfully resolved server to 122.184.75.61
2024-11-16 15:17:38 __main__     INFO     Connected to SMTP server
2024-11-16 15:17:46 __main__     ERROR    An error occurred while sending the email: (535, b'5.7.8 Error: authentication failed:')
2024-11-16 15:17:46 __main__     ERROR    An error occurred while sending the email:
Traceback (most recent call last):
  File "E:\RSSB\DCC\LPR\Codes\2024\emailSender\main.py", line 122, in <module>
    send_email_with_attachment(config)
  File "E:\RSSB\DCC\LPR\Codes\2024\emailSender\main.py", line 108, in send_email_with_attachment
    server.login(sender_email, password)
  File "C:\Users\userh\AppData\Local\Programs\Python\Python39\lib\smtplib.py", line 750, in login
    raise last_exception
  File "C:\Users\userh\AppData\Local\Programs\Python\Python39\lib\smtplib.py", line 739, in login
    (code, resp) = self.auth(
  File "C:\Users\userh\AppData\Local\Programs\Python\Python39\lib\smtplib.py", line 662, in auth
    raise SMTPAuthenticationError(code, resp)
smtplib.SMTPAuthenticationError: (535, b'5.7.8 Error: authentication failed:')
2024-11-16 15:18:28 __main__     INFO     Preparing to send email...
2024-11-16 15:18:28 __main__     INFO     Sender: "systemalert@mail.dccmail.in"
2024-11-16 15:18:28 __main__     INFO     To: ["user.harpreetsingh@gmail.com"]
2024-11-16 15:18:28 __main__     INFO     Cc: []
2024-11-16 15:18:28 __main__     INFO     Subject: "LPR Email"
2024-11-16 15:18:28 __main__     INFO     Attachment: email_sender.log
2024-11-16 15:18:28 __main__     DEBUG    Email body attached
2024-11-16 15:18:28 __main__     DEBUG    File email_sender.log read successfully
2024-11-16 15:18:28 __main__     DEBUG    File encoded successfully
2024-11-16 15:18:28 __main__     DEBUG    Attachment added to message
2024-11-16 15:18:28 __main__     INFO     Attempting to connect to SMTP server: "mail.dccmail.in"
2024-11-16 15:18:28 __main__     INFO     Successfully resolved server to 112.196.90.187
2024-11-16 15:18:28 __main__     INFO     Connected to SMTP server
2024-11-16 15:18:36 __main__     ERROR    An error occurred while sending the email: (535, b'5.7.8 Error: authentication failed:')
2024-11-16 15:18:36 __main__     ERROR    An error occurred while sending the email:
Traceback (most recent call last):
  File "E:\RSSB\DCC\LPR\Codes\2024\emailSender\main.py", line 122, in <module>
    send_email_with_attachment(config)
  File "E:\RSSB\DCC\LPR\Codes\2024\emailSender\main.py", line 108, in send_email_with_attachment
    server.login(sender_email, password)
  File "C:\Users\userh\AppData\Local\Programs\Python\Python39\lib\smtplib.py", line 750, in login
    raise last_exception
  File "C:\Users\userh\AppData\Local\Programs\Python\Python39\lib\smtplib.py", line 739, in login
    (code, resp) = self.auth(
  File "C:\Users\userh\AppData\Local\Programs\Python\Python39\lib\smtplib.py", line 662, in auth
    raise SMTPAuthenticationError(code, resp)
smtplib.SMTPAuthenticationError: (535, b'5.7.8 Error: authentication failed:')
2024-11-16 15:20:33 __main__     INFO     Preparing to send email...
2024-11-16 15:20:33 __main__     INFO     Sender: 'systemalert@mail.dccmail.in'
2024-11-16 15:20:33 __main__     INFO     To: ["user.harpreetsingh@gmail.com"]
2024-11-16 15:20:33 __main__     INFO     Cc: []
2024-11-16 15:20:33 __main__     INFO     Subject: "LPR Email"
2024-11-16 15:20:33 __main__     INFO     Attachment: email_sender.log
2024-11-16 15:20:33 __main__     DEBUG    Email body attached
2024-11-16 15:20:33 __main__     DEBUG    File email_sender.log read successfully
2024-11-16 15:20:33 __main__     DEBUG    File encoded successfully
2024-11-16 15:20:33 __main__     DEBUG    Attachment added to message
2024-11-16 15:20:33 __main__     INFO     Attempting to connect to SMTP server: 'mail.dccmail.in'
2024-11-16 15:20:33 __main__     ERROR    Failed to resolve server: [Errno 11001] getaddrinfo failed
2024-11-16 15:20:33 __main__     ERROR    An error occurred while sending the email: [Errno 11001] getaddrinfo failed
2024-11-16 15:20:33 __main__     ERROR    An error occurred while sending the email:
Traceback (most recent call last):
  File "E:\RSSB\DCC\LPR\Codes\2024\emailSender\main.py", line 122, in <module>
    send_email_with_attachment(config)
  File "E:\RSSB\DCC\LPR\Codes\2024\emailSender\main.py", line 97, in send_email_with_attachment
    server_ip = socket.gethostbyname(smtp_server)
socket.gaierror: [Errno 11001] getaddrinfo failed
2024-11-16 15:20:50 __main__     INFO     Preparing to send email...
2024-11-16 15:20:50 __main__     INFO     Sender: 'systemalert@mail.dccmail.in'
2024-11-16 15:20:50 __main__     INFO     To: ["user.harpreetsingh@gmail.com"]
2024-11-16 15:20:50 __main__     INFO     Cc: []
2024-11-16 15:20:50 __main__     INFO     Subject: "LPR Email"
2024-11-16 15:20:50 __main__     INFO     Attachment: email_sender.log
2024-11-16 15:20:50 __main__     DEBUG    Email body attached
2024-11-16 15:20:50 __main__     DEBUG    File email_sender.log read successfully
2024-11-16 15:20:50 __main__     DEBUG    File encoded successfully
2024-11-16 15:20:50 __main__     DEBUG    Attachment added to message
2024-11-16 15:20:50 __main__     INFO     Attempting to connect to SMTP server: mail.dccmail.in
2024-11-16 15:20:50 __main__     INFO     Successfully resolved server to 112.196.90.187
2024-11-16 15:20:50 __main__     INFO     Connected to SMTP server
2024-11-16 15:20:58 __main__     ERROR    An error occurred while sending the email: (535, b'5.7.8 Error: authentication failed:')
2024-11-16 15:20:58 __main__     ERROR    An error occurred while sending the email:
Traceback (most recent call last):
  File "E:\RSSB\DCC\LPR\Codes\2024\emailSender\main.py", line 122, in <module>
    send_email_with_attachment(config)
  File "E:\RSSB\DCC\LPR\Codes\2024\emailSender\main.py", line 108, in send_email_with_attachment
    server.login(sender_email, password)
  File "C:\Users\userh\AppData\Local\Programs\Python\Python39\lib\smtplib.py", line 750, in login
    raise last_exception
  File "C:\Users\userh\AppData\Local\Programs\Python\Python39\lib\smtplib.py", line 739, in login
    (code, resp) = self.auth(
  File "C:\Users\userh\AppData\Local\Programs\Python\Python39\lib\smtplib.py", line 662, in auth
    raise SMTPAuthenticationError(code, resp)
smtplib.SMTPAuthenticationError: (535, b'5.7.8 Error: authentication failed:')
2024-11-16 15:21:05 __main__     INFO     Preparing to send email...
2024-11-16 15:21:05 __main__     INFO     Sender: systemalert@mail.dccmail.in
2024-11-16 15:21:05 __main__     INFO     To: ["user.harpreetsingh@gmail.com"]
2024-11-16 15:21:05 __main__     INFO     Cc: []
2024-11-16 15:21:05 __main__     INFO     Subject: "LPR Email"
2024-11-16 15:21:05 __main__     INFO     Attachment: email_sender.log
2024-11-16 15:21:05 __main__     DEBUG    Email body attached
2024-11-16 15:21:05 __main__     DEBUG    File email_sender.log read successfully
2024-11-16 15:21:05 __main__     DEBUG    File encoded successfully
2024-11-16 15:21:05 __main__     DEBUG    Attachment added to message
2024-11-16 15:21:05 __main__     INFO     Attempting to connect to SMTP server: mail.dccmail.in
2024-11-16 15:21:05 __main__     INFO     Successfully resolved server to 112.196.90.187
2024-11-16 15:21:05 __main__     INFO     Connected to SMTP server
2024-11-16 15:21:13 __main__     INFO     Logged in successfully
2024-11-16 15:21:13 __main__     ERROR    An error occurred while sending the email: {'["user.harpreetsingh@gmail.com"]': (501, b'5.1.3 Bad recipient address syntax'), '[]': (504, b'5.5.2 <[]>: Recipient address rejected: need fully-qualified address')}
2024-11-16 15:21:13 __main__     ERROR    An error occurred while sending the email:
Traceback (most recent call last):
  File "E:\RSSB\DCC\LPR\Codes\2024\emailSender\main.py", line 122, in <module>
    send_email_with_attachment(config)
  File "E:\RSSB\DCC\LPR\Codes\2024\emailSender\main.py", line 110, in send_email_with_attachment
    server.sendmail(sender_email, all_recipients, text)
  File "C:\Users\userh\AppData\Local\Programs\Python\Python39\lib\smtplib.py", line 901, in sendmail
    raise SMTPRecipientsRefused(senderrs)
smtplib.SMTPRecipientsRefused: {'["user.harpreetsingh@gmail.com"]': (501, b'5.1.3 Bad recipient address syntax'), '[]': (504, b'5.5.2 <[]>: Recipient address rejected: need fully-qualified address')}
2024-11-16 15:21:54 __main__     INFO     Preparing to send email...
2024-11-16 15:21:54 __main__     INFO     Sender: systemalert@mail.dccmail.in
2024-11-16 15:21:54 __main__     INFO     To: [user.harpreetsingh@gmail.com]
2024-11-16 15:21:54 __main__     INFO     Cc: [anmol.verma4@gmail.com]
2024-11-16 15:21:54 __main__     INFO     Subject: "LPR Email"
2024-11-16 15:21:54 __main__     INFO     Attachment: email_sender.log
2024-11-16 15:21:54 __main__     DEBUG    Email body attached
2024-11-16 15:21:54 __main__     DEBUG    File email_sender.log read successfully
2024-11-16 15:21:54 __main__     DEBUG    File encoded successfully
2024-11-16 15:21:54 __main__     DEBUG    Attachment added to message
2024-11-16 15:21:54 __main__     INFO     Attempting to connect to SMTP server: mail.dccmail.in
2024-11-16 15:21:54 __main__     INFO     Successfully resolved server to 112.196.90.187
2024-11-16 15:21:54 __main__     INFO     Connected to SMTP server
2024-11-16 15:21:54 __main__     INFO     Logged in successfully
2024-11-16 15:21:54 __main__     ERROR    An error occurred while sending the email: {'[user.harpreetsingh@gmail.com]': (501, b'5.1.3 Bad recipient address syntax'), '[anmol.verma4@gmail.com]': (501, b'5.1.3 Bad recipient address syntax')}
2024-11-16 15:21:54 __main__     ERROR    An error occurred while sending the email:
Traceback (most recent call last):
  File "E:\RSSB\DCC\LPR\Codes\2024\emailSender\main.py", line 122, in <module>
    send_email_with_attachment(config)
  File "E:\RSSB\DCC\LPR\Codes\2024\emailSender\main.py", line 110, in send_email_with_attachment
    server.sendmail(sender_email, all_recipients, text)
  File "C:\Users\userh\AppData\Local\Programs\Python\Python39\lib\smtplib.py", line 901, in sendmail
    raise SMTPRecipientsRefused(senderrs)
smtplib.SMTPRecipientsRefused: {'[user.harpreetsingh@gmail.com]': (501, b'5.1.3 Bad recipient address syntax'), '[anmol.verma4@gmail.com]': (501, b'5.1.3 Bad recipient address syntax')}
2024-11-16 15:22:47 __main__     INFO     Preparing to send email...
2024-11-16 15:22:47 __main__     INFO     Sender: systemalert@mail.dccmail.in
2024-11-16 15:22:47 __main__     INFO     To: ["user.harpreetsingh@gmail.com"]
2024-11-16 15:22:47 __main__     INFO     Cc: ["anmol.verma4@gmail.com"]
2024-11-16 15:22:47 __main__     INFO     Subject: "LPR Email"
2024-11-16 15:22:47 __main__     INFO     Attachment: email_sender.log
2024-11-16 15:22:47 __main__     DEBUG    Email body attached
2024-11-16 15:22:47 __main__     DEBUG    File email_sender.log read successfully
2024-11-16 15:22:47 __main__     DEBUG    File encoded successfully
2024-11-16 15:22:47 __main__     DEBUG    Attachment added to message
2024-11-16 15:22:47 __main__     INFO     Attempting to connect to SMTP server: mail.dccmail.in
2024-11-16 15:22:47 __main__     INFO     Successfully resolved server to 112.196.90.187
2024-11-16 15:22:47 __main__     INFO     Connected to SMTP server
2024-11-16 15:22:47 __main__     INFO     Logged in successfully
2024-11-16 15:22:47 __main__     ERROR    An error occurred while sending the email: {'["user.harpreetsingh@gmail.com"]': (501, b'5.1.3 Bad recipient address syntax'), '["anmol.verma4@gmail.com"]': (501, b'5.1.3 Bad recipient address syntax')}
2024-11-16 15:22:47 __main__     ERROR    An error occurred while sending the email:
Traceback (most recent call last):
  File "E:\RSSB\DCC\LPR\Codes\2024\emailSender\main.py", line 122, in <module>
    send_email_with_attachment(config)
  File "E:\RSSB\DCC\LPR\Codes\2024\emailSender\main.py", line 110, in send_email_with_attachment
    server.sendmail(sender_email, all_recipients, text)
  File "C:\Users\userh\AppData\Local\Programs\Python\Python39\lib\smtplib.py", line 901, in sendmail
    raise SMTPRecipientsRefused(senderrs)
smtplib.SMTPRecipientsRefused: {'["user.harpreetsingh@gmail.com"]': (501, b'5.1.3 Bad recipient address syntax'), '["anmol.verma4@gmail.com"]': (501, b'5.1.3 Bad recipient address syntax')}
2024-11-16 15:23:06 __main__     INFO     Preparing to send email...
2024-11-16 15:23:06 __main__     INFO     Sender: systemalert@mail.dccmail.in
2024-11-16 15:23:06 __main__     INFO     To: [user.harpreetsingh@gmail.com]
2024-11-16 15:23:06 __main__     INFO     Cc: [anmol.verma4@gmail.com]
2024-11-16 15:23:06 __main__     INFO     Subject: "LPR Email"
2024-11-16 15:23:06 __main__     INFO     Attachment: email_sender.log
2024-11-16 15:23:06 __main__     DEBUG    Email body attached
2024-11-16 15:23:06 __main__     DEBUG    File email_sender.log read successfully
2024-11-16 15:23:06 __main__     DEBUG    File encoded successfully
2024-11-16 15:23:06 __main__     DEBUG    Attachment added to message
2024-11-16 15:23:06 __main__     INFO     Attempting to connect to SMTP server: mail.dccmail.in
2024-11-16 15:23:06 __main__     INFO     Successfully resolved server to 112.196.90.187
2024-11-16 15:23:06 __main__     INFO     Connected to SMTP server
2024-11-16 15:23:06 __main__     INFO     Logged in successfully
2024-11-16 15:23:06 __main__     ERROR    An error occurred while sending the email: {'[user.harpreetsingh@gmail.com]': (501, b'5.1.3 Bad recipient address syntax'), '[anmol.verma4@gmail.com]': (501, b'5.1.3 Bad recipient address syntax')}
2024-11-16 15:23:06 __main__     ERROR    An error occurred while sending the email:
Traceback (most recent call last):
  File "E:\RSSB\DCC\LPR\Codes\2024\emailSender\main.py", line 122, in <module>
    send_email_with_attachment(config)
  File "E:\RSSB\DCC\LPR\Codes\2024\emailSender\main.py", line 110, in send_email_with_attachment
    server.sendmail(sender_email, all_recipients, text)
  File "C:\Users\userh\AppData\Local\Programs\Python\Python39\lib\smtplib.py", line 901, in sendmail
    raise SMTPRecipientsRefused(senderrs)
smtplib.SMTPRecipientsRefused: {'[user.harpreetsingh@gmail.com]': (501, b'5.1.3 Bad recipient address syntax'), '[anmol.verma4@gmail.com]': (501, b'5.1.3 Bad recipient address syntax')}
2024-11-16 15:23:17 __main__     INFO     Preparing to send email...
2024-11-16 15:23:17 __main__     INFO     Sender: systemalert@mail.dccmail.in
2024-11-16 15:23:17 __main__     INFO     To: ['user.harpreetsingh@gmail.com']
2024-11-16 15:23:17 __main__     INFO     Cc: ['anmol.verma4@gmail.com']
2024-11-16 15:23:17 __main__     INFO     Subject: "LPR Email"
2024-11-16 15:23:17 __main__     INFO     Attachment: email_sender.log
2024-11-16 15:23:17 __main__     DEBUG    Email body attached
2024-11-16 15:23:17 __main__     DEBUG    File email_sender.log read successfully
2024-11-16 15:23:17 __main__     DEBUG    File encoded successfully
2024-11-16 15:23:17 __main__     DEBUG    Attachment added to message
2024-11-16 15:23:17 __main__     INFO     Attempting to connect to SMTP server: mail.dccmail.in
2024-11-16 15:23:17 __main__     INFO     Successfully resolved server to 112.196.90.187
2024-11-16 15:23:17 __main__     INFO     Connected to SMTP server
2024-11-16 15:23:17 __main__     INFO     Logged in successfully
2024-11-16 15:23:17 __main__     ERROR    An error occurred while sending the email: {"['user.harpreetsingh@gmail.com']": (501, b'5.1.3 Bad recipient address syntax'), "['anmol.verma4@gmail.com']": (501, b'5.1.3 Bad recipient address syntax')}
2024-11-16 15:23:17 __main__     ERROR    An error occurred while sending the email:
Traceback (most recent call last):
  File "E:\RSSB\DCC\LPR\Codes\2024\emailSender\main.py", line 122, in <module>
    send_email_with_attachment(config)
  File "E:\RSSB\DCC\LPR\Codes\2024\emailSender\main.py", line 110, in send_email_with_attachment
    server.sendmail(sender_email, all_recipients, text)
  File "C:\Users\userh\AppData\Local\Programs\Python\Python39\lib\smtplib.py", line 901, in sendmail
    raise SMTPRecipientsRefused(senderrs)
smtplib.SMTPRecipientsRefused: {"['user.harpreetsingh@gmail.com']": (501, b'5.1.3 Bad recipient address syntax'), "['anmol.verma4@gmail.com']": (501, b'5.1.3 Bad recipient address syntax')}
2024-11-16 15:28:14 __main__     INFO     Preparing to send email...
2024-11-16 15:28:14 __main__     INFO     Sender: systemalert@mail.dccmail.in
2024-11-16 15:28:14 __main__     INFO     To: user.harpreetsingh@gmail.com,  anmol.verma4@gmail.com
2024-11-16 15:28:14 __main__     INFO     Cc: 
2024-11-16 15:28:14 __main__     INFO     Subject: "LPR Email"
2024-11-16 15:28:14 __main__     INFO     Attachment: email_sender.log
2024-11-16 15:28:14 __main__     DEBUG    Email body attached
2024-11-16 15:28:14 __main__     DEBUG    File email_sender.log read successfully
2024-11-16 15:28:14 __main__     DEBUG    File encoded successfully
2024-11-16 15:28:14 __main__     DEBUG    Attachment added to message
2024-11-16 15:28:14 __main__     INFO     Attempting to connect to SMTP server: mail.dccmail.in
2024-11-16 15:28:14 __main__     INFO     Successfully resolved server to 122.184.75.61
2024-11-16 15:28:15 __main__     INFO     Connected to SMTP server
2024-11-16 15:28:15 __main__     INFO     Logged in successfully
2024-11-16 15:28:15 __main__     INFO     Email sent successfully!
2024-11-16 15:28:15 __main__     INFO     Email sending process completed
